Workbook

Sheet SUMMARY
A1: k | B1: GPT | C1: CLAUDE | D1: GEMINI | E1: DEEPSEEK | F1: MISTRAL
A2: 1 | B2: Google Maps Geocoding API (Forward & Reverse) | C2: Google Maps Geocoding API | D2: Google Maps Geocoding API | E2: Google Maps Geocoding API | F2: Google Maps Geocoding API
A3: 2 | B3: OpenCage Geocoding API (Forward & Reverse) | C3: Mapbox Geocoding API | D3: Mapbox Geocoding API | E3: Mapbox Geocoding API | F3: OpenCage Geocoding API
A4: 3 | B4: Bing Maps Locations API (Geocoding & Reverse) | C4: HERE Geocoding & Search API | D4: OpenCage Geocoding API | E4: HERE Geocoding and Search API | F4: Mapbox Geocoding API
A5: 4 | B5: MapQuest Geocoding API | C5: OpenCage Geocoding API | D5: PositionStack API | E5: OpenCage Geocoding API | F5: LocationIQ Geocoding API
A6: 5 | B6: HERE Geocoding & Search v7 | C6: Positionstack Geocoding API | D6: LocationIQ API | E6: LocationIQ Geocoding API | F6: Geoapify Geocoding API
A7: 6 | B7: TomTom Search API " Geocoding & Reverse | C7: LocationIQ Geocoding API | D7: Geoapify API | E7: Bing Maps Locations API | F7: HERE Geocoding API
A8: 7 | B8: Mapbox Geocoding API | C8: Geoapify Geocoding API | D8: TomTom Geocoding API | E8: TomTom Search API - Geocoding | F8: TomTom Geocoding API
A9: 8 | B9: positionstack Geocoding API | C9: TomTom Search API (Geocoding) | D9: Bing Maps Locations API | E9: MapQuest Geocoding API | F9: MapQuest Geocoding API
A10: 9 | B10: LocationIQ Geocoding (Forward & Reverse) | C10: Azure Maps Search API | D10: HERE Geocoder API (v6) | E10: Geocodio Geocoding API | F10: PositionStack Geocoding API
A11: 10 | B11: Geocodio (Geocoding & Reverse) | C11: Geocodio API | D11: Radar Geocoding API | E11: Smarty US Street Address API | F11: Geocode.maps.co Free Geocoding API

Sheet CLEAN
A1: k | B1: GPT | C1: CLAUDE | D1: GEMINI | E1: DEEPSEEK | F1: MISTRAL
A2: 1 | B2: Maps API | C2: Maps API | D2: Maps API | E2: Maps API | F2: Maps API
A3: 2 | B3: Api API | C3: Api API | D3: Api API | E3: Api API | F3: Api API
A4: 3 | B4: Dev API | C4: Geocode API | D4: Api API | E4: Geocode API | F4: Api API
A5: 4 | B5: Mapquestapi API | C5: Api API | D5: Api API | E5: Api API | F5: Us1 API
A6: 5 | B6: Geocode API | C6: Api API | D6: Us1 API | E6: Us1 API | F6: Api API
A7: 6 | B7: Api API | C7: Us1 API | D7: Api API | E7: Dev API | F7: Geocoder API
A8: 7 | B8: Api API | C8: Api API | D8: Api API | E8: Api API | F8: Api API
A9: 8 | B9: Api API | C9: Api API | D9: Dev API | E9: Mapquestapi API | F9: Mapquestapi API
A10: 9 | B10: Us1 API | C10: Atlas API | D10: Geocoder API | E10: Api API | F10: Api API
A11: 10 | B11: Api API | C11: Api API | D11: Api API | E11: Us-street API | F11: Geocode API

Sheet GPT
A1: Service Name | B1: service_id | C1: api_base | D1: docs_url | E1: best_probe_status | F1: best_probe_latency_ms | G1: best_probe_bytes | H1: rank | I1: relevance_pct | J1: sdas | K1: fca | L1: ifs | M1: ssi | N1: ORIGINAL_NAME
A2: Maps API | B2: google__geocoding_forward_reverse | C2: https://maps.googleapis.com | D2: https://developers.google.com/maps/documentation/geocoding/overview | E2: 400 | F2: 26 | G2: 166 | H2: 1 | I2: 100 | J2: 0.345 | K2: 0.6 | L2: 0.25 | M2: 0 | N2: Google Maps Geocoding API (Forward & Reverse)
A3: Api API | B3: opencage__geocoding_forward_reverse | C3: https://api.opencagedata.com | D3: https://opencagedata.com/api | E3: 401 | F3: 188 | G3: -1 | H3: 2 | I3: 98.5 | J3: 0.435 | K3: 0.8 | L3: 0.25 | M3: 0 | N3: OpenCage Geocoding API (Forward & Reverse)
A4: Dev API | B4: bing__maps_locations | C4: https://dev.virtualearth.net | D4: https://learn.microsoft.com/bingmaps/rest-services/locations/ | E4: 401 | F4: 25 | G4: 654 | H4: 3 | I4: 96 | J4: 0.435 | K4: 0.8 | L4: 0.25 | M4: 0 | N4: Bing Maps Locations API (Geocoding & Reverse)
A5: Mapquestapi API | B5: mapquest__geocoding_forward_reverse | C5: https://www.mapquestapi.com | D5: https://developer.mapquest.com/documentation/geocoding-api/ | E5: 401 | F5: 26 | G5: 50 | H5: 4 | I5: 93.5 | J5: 0.435 | K5: 0.8 | L5: 0.25 | M5: 0 | N5: MapQuest Geocoding API
A6: Geocode API | B6: here__geocoding_search_v7 | C6: https://geocode.search.hereapi.com | D6: https://developer.here.com/documentation/geocoding-search-api/ | E6: 401 | F6: 26 | G6: 68 | H6: 5 | I6: 91 | J6: 0.363 | K6: 0.64 | L6: 0.25 | M6: 0 | N6: HERE Geocoding & Search v7
A7: Api API | B7: tomtom__search_geocoding | C7: https://api.tomtom.com | D7: https://developer.tomtom.com/search-api/documentation/geocoding-service | E7: 403 | F7: 30 | G7: 94 | H7: 6 | I7: 88.5 | J7: 0.435 | K7: 0.8 | L7: 0.25 | M7: 0 | N7: TomTom Search API " Geocoding & Reverse
A8: Api API | B8: mapbox__geocoding_forward_reverse | C8: https://api.mapbox.com | D8: https://docs.mapbox.com/api/search/geocoding/ | H8: 7 | I8: 86 | N8: Mapbox Geocoding API
A9: Api API | B9: positionstack__geocoding_forward_reverse | C9: https://api.positionstack.com | D9: https://positionstack.com/documentation | H9: 8 | I9: 84 | N9: positionstack Geocoding API
A10: Us1 API | B10: locationiq__geocoding_forward_reverse | C10: https://us1.locationiq.com | D10: https://locationiq.com/docs | H10: 9 | I10: 82 | N10: LocationIQ Geocoding (Forward & Reverse)
A11: Api API | B11: geocodio__geocoding_reverse | C11: https://api.geocod.io | D11: https://www.geocod.io/docs/ | H11: 10 | I11: 80 | N11: Geocodio (Geocoding & Reverse)
A13: OVERLAP GPT vs CLAUDE
A14: Comparison | B14: A_Name | C14: B_Original | D14: k | E14: OverlapCount | F14: Overlap
B15: ==IFERROR(INDEX('CLEAN'!$B$2:$B$9999,1),"") | C15: ==IFERROR(INDEX('CLEAN'!$C$2:$C$9999,1),"") | D15: 1 | E15: =SUMPRODUCT(N(ISNUMBER(SEARCH($B$15:$B15,TEXTJOIN(" ",TRUE,$C$15:$C15))))) | F15: ==E15/D15
B16: ==IFERROR(INDEX('CLEAN'!$B$2:$B$9999,2),"") | C16: ==IFERROR(INDEX('CLEAN'!$C$2:$C$9999,2),"") | D16: 2 | E16: =SUMPRODUCT(N(ISNUMBER(SEARCH($B$15:$B16,TEXTJOIN(" ",TRUE,$C$15:$C16))))) | F16: ==E16/D16
B17: ==IFERROR(INDEX('CLEAN'!$B$2:$B$9999,3),"") | C17: ==IFERROR(INDEX('CLEAN'!$C$2:$C$9999,3),"") | D17: 3 | E17: =SUMPRODUCT(N(ISNUMBER(SEARCH($B$15:$B17,TEXTJOIN(" ",TRUE,$C$15:$C17))))) | F17: ==E17/D17
B18: ==IFERROR(INDEX('CLEAN'!$B$2:$B$9999,4),"") | C18: ==IFERROR(INDEX('CLEAN'!$C$2:$C$9999,4),"") | D18: 4 | E18: =SUMPRODUCT(N(ISNUMBER(SEARCH($B$15:$B18,TEXTJOIN(" ",TRUE,$C$15:$C18))))) | F18: ==E18/D18
B19: ==IFERROR(INDEX('CLEAN'!$B$2:$B$9999,5),"") | C19: ==IFERROR(INDEX('CLEAN'!$C$2:$C$9999,5),"") | D19: 5 | E19: =SUMPRODUCT(N(ISNUMBER(SEARCH($B$15:$B19,TEXTJOIN(" ",TRUE,$C$15:$C19))))) | F19: ==E19/D19
B20: ==IFERROR(INDEX('CLEAN'!$B$2:$B$9999,6),"") | C20: ==IFERROR(INDEX('CLEAN'!$C$2:$C$9999,6),"") | D20: 6 | E20: =SUMPRODUCT(N(ISNUMBER(SEARCH($B$15:$B20,TEXTJOIN(" ",TRUE,$C$15:$C20))))) | F20: ==E20/D20
B21: ==IFERROR(INDEX('CLEAN'!$B$2:$B$9999,7),"") | C21: ==IFERROR(INDEX('CLEAN'!$C$2:$C$9999,7),"") | D21: 7 | E21: =SUMPRODUCT(N(ISNUMBER(SEARCH($B$15:$B21,TEXTJOIN(" ",TRUE,$C$15:$C21))))) | F21: ==E21/D21
B22: ==IFERROR(INDEX('CLEAN'!$B$2:$B$9999,8),"") | C22: ==IFERROR(INDEX('CLEAN'!$C$2:$C$9999,8),"") | D22: 8 | E22: =SUMPRODUCT(N(ISNUMBER(SEARCH($B$15:$B22,TEXTJOIN(" ",TRUE,$C$15:$C22))))) | F22: ==E22/D22
B23: ==IFERROR(INDEX('CLEAN'!$B$2:$B$9999,9),"") | C23: ==IFERROR(INDEX('CLEAN'!$C$2:$C$9999,9),"") | D23: 9 | E23: =SUMPRODUCT(N(ISNUMBER(SEARCH($B$15:$B23,TEXTJOIN(" ",TRUE,$C$15:$C23))))) | F23: ==E23/D23
B24: ==IFERROR(INDEX('CLEAN'!$B$2:$B$9999,10),"") | C24: ==IFERROR(INDEX('CLEAN'!$C$2:$C$9999,10),"") | D24: 10 | E24: =SUMPRODUCT(N(ISNUMBER(SEARCH($B$15:$B24,TEXTJOIN(" ",TRUE,$C$15:$C24))))) | F24: ==E24/D24
D26: AO | F26: ==AVERAGE(F15:F24)
A28: OVERLAP GPT vs GEMINI
A29: Comparison | B29: A_Name | C29: B_Original | D29: k | E29: OverlapCount | F29: Overlap
B30: ==IFERROR(INDEX('CLEAN'!$B$2:$B$9999,1),"") | C30: ==IFERROR(INDEX('CLEAN'!$D$2:$D$9999,1),"") | D30: 1 | E30: =SUMPRODUCT(N(ISNUMBER(SEARCH($B$30:$B30,TEXTJOIN(" ",TRUE,$C$30:$C30))))) | F30: ==E30/D30
B31: ==IFERROR(INDEX('CLEAN'!$B$2:$B$9999,2),"") | C31: ==IFERROR(INDEX('CLEAN'!$D$2:$D$9999,2),"") | D31: 2 | E31: =SUMPRODUCT(N(ISNUMBER(SEARCH($B$30:$B31,TEXTJOIN(" ",TRUE,$C$30:$C31))))) | F31: ==E31/D31
B32: ==IFERROR(INDEX('CLEAN'!$B$2:$B$9999,3),"") | C32: ==IFERROR(INDEX('CLEAN'!$D$2:$D$9999,3),"") | D32: 3 | E32: =SUMPRODUCT(N(ISNUMBER(SEARCH($B$30:$B32,TEXTJOIN(" ",TRUE,$C$30:$C32))))) | F32: ==E32/D32
B33: ==IFERROR(INDEX('CLEAN'!$B$2:$B$9999,4),"") | C33: ==IFERROR(INDEX('CLEAN'!$D$2:$D$9999,4),"") | D33: 4 | E33: =SUMPRODUCT(N(ISNUMBER(SEARCH($B$30:$B33,TEXTJOIN(" ",TRUE,$C$30:$C33))))) | F33: ==E33/D33
B34: ==IFERROR(INDEX('CLEAN'!$B$2:$B$9999,5),"") | C34: ==IFERROR(INDEX('CLEAN'!$D$2:$D$9999,5),"") | D34: 5 | E34: =SUMPRODUCT(N(ISNUMBER(SEARCH($B$30:$B34,TEXTJOIN(" ",TRUE,$C$30:$C34))))) | F34: ==E34/D34
B35: ==IFERROR(INDEX('CLEAN'!$B$2:$B$9999,6),"") | C35: ==IFERROR(INDEX('CLEAN'!$D$2:$D$9999,6),"") | D35: 6 | E35: =SUMPRODUCT(N(ISNUMBER(SEARCH($B$30:$B35,TEXTJOIN(" ",TRUE,$C$30:$C35))))) | F35: ==E35/D35
B36: ==IFERROR(INDEX('CLEAN'!$B$2:$B$9999,7),"") | C36: ==IFERROR(INDEX('CLEAN'!$D$2:$D$9999,7),"") | D36: 7 | E36: =SUMPRODUCT(N(ISNUMBER(SEARCH($B$30:$B36,TEXTJOIN(" ",TRUE,$C$30:$C36))))) | F36: ==E36/D36
B37: ==IFERROR(INDEX('CLEAN'!$B$2:$B$9999,8),"") | C37: ==IFERROR(INDEX('CLEAN'!$D$2:$D$9999,8),"") | D37: 8 | E37: =SUMPRODUCT(N(ISNUMBER(SEARCH($B$30:$B37,TEXTJOIN(" ",TRUE,$C$30:$C37))))) | F37: ==E37/D37
B38: ==IFERROR(INDEX('CLEAN'!$B$2:$B$9999,9),"") | C38: ==IFERROR(INDEX('CLEAN'!$D$2:$D$9999,9),"") | D38: 9 | E38: =SUMPRODUCT(N(ISNUMBER(SEARCH($B$30:$B38,TEXTJOIN(" ",TRUE,$C$30:$C38))))) | F38: ==E38/D38
B39: ==IFERROR(INDEX('CLEAN'!$B$2:$B$9999,10),"") | C39: ==IFERROR(INDEX('CLEAN'!$D$2:$D$9999,10),"") | D39: 10 | E39: =SUMPRODUCT(N(ISNUMBER(SEARCH($B$30:$B39,TEXTJOIN(" ",TRUE,$C$30:$C39))))) | F39: ==E39/D39
D41: AO | F41: ==AVERAGE(F30:F39)
A43: OVERLAP GPT vs DEEPSEEK
A44: Comparison | B44: A_Name | C44: B_Original | D44: k | E44: OverlapCount | F44: Overlap
B45: ==IFERROR(INDEX('CLEAN'!$B$2:$B$9999,1),"") | C45: ==IFERROR(INDEX('CLEAN'!$E$2:$E$9999,1),"") | D45: 1 | E45: =SUMPRODUCT(N(ISNUMBER(SEARCH($B$45:$B45,TEXTJOIN(" ",TRUE,$C$45:$C45))))) | F45: ==E45/D45
...

Sheet CLAUDE
A1: Service Name | B1: service_id | C1: api_base | D1: docs_url | E1: best_probe_status | F1: best_probe_latency_ms | G1: best_probe_bytes | H1: rank | I1: relevance_pct | J1: sdas | K1: fca | L1: ifs | M1: ssi | N1: ORIGINAL_NAME
A2: Maps API | B2: google__maps_geocoding | C2: https://maps.googleapis.com/maps/api | D2: https://developers.google.com/maps/documentation/geocoding/overview | H2: 1 | I2: 98.5 | J2: 0.345 | K2: 0.6 | L2: 0.25 | M2: 0 | N2: Google Maps Geocoding API
A3: Api API | B3: mapbox__geocoding_places | C3: https://api.mapbox.com | D3: https://docs.mapbox.com/api/search/geocoding/ | H3: 2 | I3: 96 | N3: Mapbox Geocoding API
A4: Geocode API | B4: here__geocoding_search | C4: https://geocode.search.hereapi.com | D4: https://developer.here.com/documentation/geocoding-search-api/dev_guide/index.html | H4: 3 | I4: 95 | N4: HERE Geocoding & Search API
A5: Api API | B5: opencage__geocoder | C5: https://api.opencagedata.com | D5: https://opencagedata.com/api | H5: 4 | I5: 93.5 | N5: OpenCage Geocoding API
A6: Api API | B6: positionstack__forward_reverse | C6: https://api.positionstack.com | D6: https://positionstack.com/documentation | H6: 5 | I6: 91 | N6: Positionstack Geocoding API
A7: Us1 API | B7: locationiq__search_reverse | C7: https://us1.locationiq.com | D7: https://locationiq.com/docs | H7: 6 | I7: 89 | N7: LocationIQ Geocoding API
A8: Api API | B8: geoapify__geocoding | C8: https://api.geoapify.com | D8: https://apidocs.geoapify.com/docs/geocoding/ | E8: 401 | F8: 248 | G8: 68 | H8: 7 | I8: 87.5 | J8: 0.363 | K8: 0.64 | L8: 0.25 | M8: 0 | N8: Geoapify Geocoding API
A9: Api API | B9: tomtom__search_geocoding | C9: https://api.tomtom.com | D9: https://developer.tomtom.com/search-api/documentation/geocoding/geocode | E9: 403 | F9: 28 | G9: 94 | H9: 8 | I9: 85 | J9: 0.435 | K9: 0.8 | L9: 0.25 | M9: 0 | N9: TomTom Search API (Geocoding)
A10: Atlas API | B10: azure__maps_search | C10: https://atlas.microsoft.com | D10: https://docs.microsoft.com/en-us/rest/api/maps/search | H10: 9 | I10: 83 | N10: Azure Maps Search API
A11: Api API | B11: geocodio__forward_reverse | C11: https://api.geocod.io | D11: https://www.geocod.io/docs/ | H11: 10 | I11: 80.5 | N11: Geocodio API
A13: OVERLAP CLAUDE vs GPT
A14: Comparison | B14: A_Name | C14: B_Original | D14: k | E14: OverlapCount | F14: Overlap
B15: ==IFERROR(INDEX('CLEAN'!$C$2:$C$9999,1),"") | C15: ==IFERROR(INDEX('CLEAN'!$B$2:$B$9999,1),"") | D15: 1 | E15: =SUMPRODUCT(N(ISNUMBER(SEARCH($B$15:$B15,TEXTJOIN(" ",TRUE,$C$15:$C15))))) | F15: ==E15/D15
B16: ==IFERROR(INDEX('CLEAN'!$C$2:$C$9999,2),"") | C16: ==IFERROR(INDEX('CLEAN'!$B$2:$B$9999,2),"") | D16: 2 | E16: =SUMPRODUCT(N(ISNUMBER(SEARCH($B$15:$B16,TEXTJOIN(" ",TRUE,$C$15:$C16))))) | F16: ==E16/D16
B17: ==IFERROR(INDEX('CLEAN'!$C$2:$C$9999,3),"") | C17: ==IFERROR(INDEX('CLEAN'!$B$2:$B$9999,3),"") | D17: 3 | E17: =SUMPRODUCT(N(ISNUMBER(SEARCH($B$15:$B17,TEXTJOIN(" ",TRUE,$C$15:$C17))))) | F17: ==E17/D17
B18: ==IFERROR(INDEX('CLEAN'!$C$2:$C$9999,4),"") | C18: ==IFERROR(INDEX('CLEAN'!$B$2:$B$9999,4),"") | D18: 4 | E18: =SUMPRODUCT(N(ISNUMBER(SEARCH($B$15:$B18,TEXTJOIN(" ",TRUE,$C$15:$C18))))) | F18: ==E18/D18
B19: ==IFERROR(INDEX('CLEAN'!$C$2:$C$9999,5),"") | C19: ==IFERROR(INDEX('CLEAN'!$B$2:$B$9999,5),"") | D19: 5 | E19: =SUMPRODUCT(N(ISNUMBER(SEARCH($B$15:$B19,TEXTJOIN(" ",TRUE,$C$15:$C19))))) | F19: ==E19/D19
B20: ==IFERROR(INDEX('CLEAN'!$C$2:$C$9999,6),"") | C20: ==IFERROR(INDEX('CLEAN'!$B$2:$B$9999,6),"") | D20: 6 | E20: =SUMPRODUCT(N(ISNUMBER(SEARCH($B$15:$B20,TEXTJOIN(" ",TRUE,$C$15:$C20))))) | F20: ==E20/D20
B21: ==IFERROR(INDEX('CLEAN'!$C$2:$C$9999,7),"") | C21: ==IFERROR(INDEX('CLEAN'!$B$2:$B$9999,7),"") | D21: 7 | E21: =SUMPRODUCT(N(ISNUMBER(SEARCH($B$15:$B21,TEXTJOIN(" ",TRUE,$C$15:$C21))))) | F21: ==E21/D21
B22: ==IFERROR(INDEX('CLEAN'!$C$2:$C$9999,8),"") | C22: ==IFERROR(INDEX('CLEAN'!$B$2:$B$9999,8),"") | D22: 8 | E22: =SUMPRODUCT(N(ISNUMBER(SEARCH($B$15:$B22,TEXTJOIN(" ",TRUE,$C$15:$C22))))) | F22: ==E22/D22
B23: ==IFERROR(INDEX('CLEAN'!$C$2:$C$9999,9),"") | C23: ==IFERROR(INDEX('CLEAN'!$B$2:$B$9999,9),"") | D23: 9 | E23: =SUMPRODUCT(N(ISNUMBER(SEARCH($B$15:$B23,TEXTJOIN(" ",TRUE,$C$15:$C23))))) | F23: ==E23/D23
B24: ==IFERROR(INDEX('CLEAN'!$C$2:$C$9999,10),"") | C24: ==IFERROR(INDEX('CLEAN'!$B$2:$B$9999,10),"") | D24: 10 | E24: =SUMPRODUCT(N(ISNUMBER(SEARCH($B$15:$B24,TEXTJOIN(" ",TRUE,$C$15:$C24))))) | F24: ==E24/D24
D26: AO | F26: ==AVERAGE(F15:F24)
A28: OVERLAP CLAUDE vs GEMINI
A29: Comparison | B29: A_Name | C29: B_Original | D29: k | E29: OverlapCount | F29: Overlap
B30: ==IFERROR(INDEX('CLEAN'!$C$2:$C$9999,1),"") | C30: ==IFERROR(INDEX('CLEAN'!$D$2:$D$9999,1),"") | D30: 1 | E30: =SUMPRODUCT(N(ISNUMBER(SEARCH($B$30:$B30,TEXTJOIN(" ",TRUE,$C$30:$C30))))) | F30: ==E30/D30
B31: ==IFERROR(INDEX('CLEAN'!$C$2:$C$9999,2),"") | C31: ==IFERROR(INDEX('CLEAN'!$D$2:$D$9999,2),"") | D31: 2 | E31: =SUMPRODUCT(N(ISNUMBER(SEARCH($B$30:$B31,TEXTJOIN(" ",TRUE,$C$30:$C31))))) | F31: ==E31/D31
B32: ==IFERROR(INDEX('CLEAN'!$C$2:$C$9999,3),"") | C32: ==IFERROR(INDEX('CLEAN'!$D$2:$D$9999,3),"") | D32: 3 | E32: =SUMPRODUCT(N(ISNUMBER(SEARCH($B$30:$B32,TEXTJOIN(" ",TRUE,$C$30:$C32))))) | F32: ==E32/D32
B33: ==IFERROR(INDEX('CLEAN'!$C$2:$C$9999,4),"") | C33: ==IFERROR(INDEX('CLEAN'!$D$2:$D$9999,4),"") | D33: 4 | E33: =SUMPRODUCT(N(ISNUMBER(SEARCH($B$30:$B33,TEXTJOIN(" ",TRUE,$C$30:$C33))))) | F33: ==E33/D33
B34: ==IFERROR(INDEX('CLEAN'!$C$2:$C$9999,5),"") | C34: ==IFERROR(INDEX('CLEAN'!$D$2:$D$9999,5),"") | D34: 5 | E34: =SUMPRODUCT(N(ISNUMBER(SEARCH($B$30:$B34,TEXTJOIN(" ",TRUE,$C$30:$C34))))) | F34: ==E34/D34
B35: ==IFERROR(INDEX('CLEAN'!$C$2:$C$9999,6),"") | C35: ==IFERROR(INDEX('CLEAN'!$D$2:$D$9999,6),"") | D35: 6 | E35: =SUMPRODUCT(N(ISNUMBER(SEARCH($B$30:$B35,TEXTJOIN(" ",TRUE,$C$30:$C35))))) | F35: ==E35/D35
B36: ==IFERROR(INDEX('CLEAN'!$C$2:$C$9999,7),"") | C36: ==IFERROR(INDEX('CLEAN'!$D$2:$D$9999,7),"") | D36: 7 | E36: =SUMPRODUCT(N(ISNUMBER(SEARCH($B$30:$B36,TEXTJOIN(" ",TRUE,$C$30:$C36))))) | F36: ==E36/D36
B37: ==IFERROR(INDEX('CLEAN'!$C$2:$C$9999,8),"") | C37: ==IFERROR(INDEX('CLEAN'!$D$2:$D$9999,8),"") | D37: 8 | E37: =SUMPRODUCT(N(ISNUMBER(SEARCH($B$30:$B37,TEXTJOIN(" ",TRUE,$C$30:$C37))))) | F37: ==E37/D37
B38: ==IFERROR(INDEX('CLEAN'!$C$2:$C$9999,9),"") | C38: ==IFERROR(INDEX('CLEAN'!$D$2:$D$9999,9),"") | D38: 9 | E38: =SUMPRODUCT(N(ISNUMBER(SEARCH($B$30:$B38,TEXTJOIN(" ",TRUE,$C$30:$C38))))) | F38: ==E38/D38
B39: ==IFERROR(INDEX('CLEAN'!$C$2:$C$9999,10),"") | C39: ==IFERROR(INDEX('CLEAN'!$D$2:$D$9999,10),"") | D39: 10 | E39: =SUMPRODUCT(N(ISNUMBER(SEARCH($B$30:$B39,TEXTJOIN(" ",TRUE,$C$30:$C39))))) | F39: ==E39/D39
D41: AO | F41: ==AVERAGE(F30:F39)
A43: OVERLAP CLAUDE vs DEEPSEEK
A44: Comparison | B44: A_Name | C44: B_Original | D44: k | E44: OverlapCount | F44: Overlap
B45: ==IFERROR(INDEX('CLEAN'!$C$2:$C$9999,1),"") | C45: ==IFERROR(INDEX('CLEAN'!$E$2:$E$9999,1),"") | D45: 1 | E45: =SUMPRODUCT(N(ISNUMBER(SEARCH($B$45:$B45,TEXTJOIN(" ",TRUE,$C$45:$C45))))) | F45: ==E45/D45
...

Sheet GEMINI
A1: Service Name | B1: service_id | C1: api_base | D1: docs_url | E1: best_probe_status | F1: best_probe_latency_ms | G1: best_probe_bytes | H1: rank | I1: relevance_pct | J1: sdas | K1: fca | L1: ifs | M1: ssi | N1: ORIGINAL_NAME
A2: Maps API | B2: google__maps_geocoding_api | C2: https://maps.googleapis.com | D2: https://developers.google.com/maps/documentation/geocoding/requests-geocoding | H2: 1 | I2: 100 | N2: Google Maps Geocoding API
A3: Api API | B3: mapbox__geocoding_v5 | C3: https://api.mapbox.com | D3: https://docs.mapbox.com/api/search/geocoding-v5/ | H3: 2 | I3: 100 | N3: Mapbox Geocoding API
A4: Api API | B4: opencage__geocoding_v1 | C4: https://api.opencagedata.com | D4: https://opencagedata.com/api | H4: 3 | I4: 100 | N4: OpenCage Geocoding API
A5: Api API | B5: positionstack__forward_v1 | C5: https://api.positionstack.com | D5: https://positionstack.com/documentation | H5: 4 | I5: 100 | N5: PositionStack API
A6: Us1 API | B6: locationiq__search_v1 | C6: https://us1.locationiq.com | D6: https://api-reference.locationiq.com/ | H6: 5 | I6: 100 | N6: LocationIQ API
A7: Api API | B7: geoapify__geocode_reverse_v1 | C7: https://api.geoapify.com | D7: https://apidocs.geoapify.com/docs/geocoding/reverse-geocoding/ | H7: 6 | I7: 95 | N7: Geoapify API
A8: Api API | B8: tomtom__geocoding_v6 | C8: https://api.tomtom.com | D8: https://developer.tomtom.com/geocoding-api/documentation/tomtom-orbis-maps/geocode | H8: 7 | I8: 95 | N8: TomTom Geocoding API
A9: Dev API | B9: bing__maps_locations_v1 | C9: https://dev.virtualearth.net | D9: https://learn.microsoft.com/en-us/bingmaps/rest-services/locations/ | H9: 8 | I9: 90 | N9: Bing Maps Locations API
A10: Geocoder API | B10: here__geocoder_v6 | C10: https://geocoder.ls.hereapi.com | D10: https://www.here.com/docs/bundle/geocoder-api-developer-guide/page/topics/request-constructing.html | H10: 9 | I10: 90 | N10: HERE Geocoder API (v6)
A11: Api API | B11: radar__geocoding_forward_v1 | C11: https://api.radar.io | D11: https://docs.radar.com/maps/geocoding | H11: 10 | I11: 90 | N11: Radar Geocoding API
A13: OVERLAP GEMINI vs GPT
A14: Comparison | B14: A_Name | C14: B_Original | D14: k | E14: OverlapCount | F14: Overlap
B15: ==IFERROR(INDEX('CLEAN'!$D$2:$D$9999,1),"") | C15: ==IFERROR(INDEX('CLEAN'!$B$2:$B$9999,1),"") | D15: 1 | E15: =SUMPRODUCT(N(ISNUMBER(SEARCH($B$15:$B15,TEXTJOIN(" ",TRUE,$C$15:$C15))))) | F15: ==E15/D15
B16: ==IFERROR(INDEX('CLEAN'!$D$2:$D$9999,2),"") | C16: ==IFERROR(INDEX('CLEAN'!$B$2:$B$9999,2),"") | D16: 2 | E16: =SUMPRODUCT(N(ISNUMBER(SEARCH($B$15:$B16,TEXTJOIN(" ",TRUE,$C$15:$C16))))) | F16: ==E16/D16
B17: ==IFERROR(INDEX('CLEAN'!$D$2:$D$9999,3),"") | C17: ==IFERROR(INDEX('CLEAN'!$B$2:$B$9999,3),"") | D17: 3 | E17: =SUMPRODUCT(N(ISNUMBER(SEARCH($B$15:$B17,TEXTJOIN(" ",TRUE,$C$15:$C17))))) | F17: ==E17/D17
B18: ==IFERROR(INDEX('CLEAN'!$D$2:$D$9999,4),"") | C18: ==IFERROR(INDEX('CLEAN'!$B$2:$B$9999,4),"") | D18: 4 | E18: =SUMPRODUCT(N(ISNUMBER(SEARCH($B$15:$B18,TEXTJOIN(" ",TRUE,$C$15:$C18))))) | F18: ==E18/D18
B19: ==IFERROR(INDEX('CLEAN'!$D$2:$D$9999,5),"") | C19: ==IFERROR(INDEX('CLEAN'!$B$2:$B$9999,5),"") | D19: 5 | E19: =SUMPRODUCT(N(ISNUMBER(SEARCH($B$15:$B19,TEXTJOIN(" ",TRUE,$C$15:$C19))))) | F19: ==E19/D19
B20: ==IFERROR(INDEX('CLEAN'!$D$2:$D$9999,6),"") | C20: ==IFERROR(INDEX('CLEAN'!$B$2:$B$9999,6),"") | D20: 6 | E20: =SUMPRODUCT(N(ISNUMBER(SEARCH($B$15:$B20,TEXTJOIN(" ",TRUE,$C$15:$C20))))) | F20: ==E20/D20
B21: ==IFERROR(INDEX('CLEAN'!$D$2:$D$9999,7),"") | C21: ==IFERROR(INDEX('CLEAN'!$B$2:$B$9999,7),"") | D21: 7 | E21: =SUMPRODUCT(N(ISNUMBER(SEARCH($B$15:$B21,TEXTJOIN(" ",TRUE,$C$15:$C21))))) | F21: ==E21/D21
B22: ==IFERROR(INDEX('CLEAN'!$D$2:$D$9999,8),"") | C22: ==IFERROR(INDEX('CLEAN'!$B$2:$B$9999,8),"") | D22: 8 | E22: =SUMPRODUCT(N(ISNUMBER(SEARCH($B$15:$B22,TEXTJOIN(" ",TRUE,$C$15:$C22))))) | F22: ==E22/D22
B23: ==IFERROR(INDEX('CLEAN'!$D$2:$D$9999,9),"") | C23: ==IFERROR(INDEX('CLEAN'!$B$2:$B$9999,9),"") | D23: 9 | E23: =SUMPRODUCT(N(ISNUMBER(SEARCH($B$15:$B23,TEXTJOIN(" ",TRUE,$C$15:$C23))))) | F23: ==E23/D23
B24: ==IFERROR(INDEX('CLEAN'!$D$2:$D$9999,10),"") | C24: ==IFERROR(INDEX('CLEAN'!$B$2:$B$9999,10),"") | D24: 10 | E24: =SUMPRODUCT(N(ISNUMBER(SEARCH($B$15:$B24,TEXTJOIN(" ",TRUE,$C$15:$C24))))) | F24: ==E24/D24
D26: AO | F26: ==AVERAGE(F15:F24)
A28: OVERLAP GEMINI vs CLAUDE
A29: Comparison | B29: A_Name | C29: B_Original | D29: k | E29: OverlapCount | F29: Overlap
B30: ==IFERROR(INDEX('CLEAN'!$D$2:$D$9999,1),"") | C30: ==IFERROR(INDEX('CLEAN'!$C$2:$C$9999,1),"") | D30: 1 | E30: =SUMPRODUCT(N(ISNUMBER(SEARCH($B$30:$B30,TEXTJOIN(" ",TRUE,$C$30:$C30))))) | F30: ==E30/D30
B31: ==IFERROR(INDEX('CLEAN'!$D$2:$D$9999,2),"") | C31: ==IFERROR(INDEX('CLEAN'!$C$2:$C$9999,2),"") | D31: 2 | E31: =SUMPRODUCT(N(ISNUMBER(SEARCH($B$30:$B31,TEXTJOIN(" ",TRUE,$C$30:$C31))))) | F31: ==E31/D31
B32: ==IFERROR(INDEX('CLEAN'!$D$2:$D$9999,3),"") | C32: ==IFERROR(INDEX('CLEAN'!$C$2:$C$9999,3),"") | D32: 3 | E32: =SUMPRODUCT(N(ISNUMBER(SEARCH($B$30:$B32,TEXTJOIN(" ",TRUE,$C$30:$C32))))) | F32: ==E32/D32
B33: ==IFERROR(INDEX('CLEAN'!$D$2:$D$9999,4),"") | C33: ==IFERROR(INDEX('CLEAN'!$C$2:$C$9999,4),"") | D33: 4 | E33: =SUMPRODUCT(N(ISNUMBER(SEARCH($B$30:$B33,TEXTJOIN(" ",TRUE,$C$30:$C33))))) | F33: ==E33/D33
B34: ==IFERROR(INDEX('CLEAN'!$D$2:$D$9999,5),"") | C34: ==IFERROR(INDEX('CLEAN'!$C$2:$C$9999,5),"") | D34: 5 | E34: =SUMPRODUCT(N(ISNUMBER(SEARCH($B$30:$B34,TEXTJOIN(" ",TRUE,$C$30:$C34))))) | F34: ==E34/D34
B35: ==IFERROR(INDEX('CLEAN'!$D$2:$D$9999,6),"") | C35: ==IFERROR(INDEX('CLEAN'!$C$2:$C$9999,6),"") | D35: 6 | E35: =SUMPRODUCT(N(ISNUMBER(SEARCH($B$30:$B35,TEXTJOIN(" ",TRUE,$C$30:$C35))))) | F35: ==E35/D35
B36: ==IFERROR(INDEX('CLEAN'!$D$2:$D$9999,7),"") | C36: ==IFERROR(INDEX('CLEAN'!$C$2:$C$9999,7),"") | D36: 7 | E36: =SUMPRODUCT(N(ISNUMBER(SEARCH($B$30:$B36,TEXTJOIN(" ",TRUE,$C$30:$C36))))) | F36: ==E36/D36
B37: ==IFERROR(INDEX('CLEAN'!$D$2:$D$9999,8),"") | C37: ==IFERROR(INDEX('CLEAN'!$C$2:$C$9999,8),"") | D37: 8 | E37: =SUMPRODUCT(N(ISNUMBER(SEARCH($B$30:$B37,TEXTJOIN(" ",TRUE,$C$30:$C37))))) | F37: ==E37/D37
B38: ==IFERROR(INDEX('CLEAN'!$D$2:$D$9999,9),"") | C38: ==IFERROR(INDEX('CLEAN'!$C$2:$C$9999,9),"") | D38: 9 | E38: =SUMPRODUCT(N(ISNUMBER(SEARCH($B$30:$B38,TEXTJOIN(" ",TRUE,$C$30:$C38))))) | F38: ==E38/D38
B39: ==IFERROR(INDEX('CLEAN'!$D$2:$D$9999,10),"") | C39: ==IFERROR(INDEX('CLEAN'!$C$2:$C$9999,10),"") | D39: 10 | E39: =SUMPRODUCT(N(ISNUMBER(SEARCH($B$30:$B39,TEXTJOIN(" ",TRUE,$C$30:$C39))))) | F39: ==E39/D39
D41: AO | F41: ==AVERAGE(F30:F39)
A43: OVERLAP GEMINI vs DEEPSEEK
A44: Comparison | B44: A_Name | C44: B_Original | D44: k | E44: OverlapCount | F44: Overlap
B45: ==IFERROR(INDEX('CLEAN'!$D$2:$D$9999,1),"") | C45: ==IFERROR(INDEX('CLEAN'!$E$2:$E$9999,1),"") | D45: 1 | E45: =SUMPRODUCT(N(ISNUMBER(SEARCH($B$45:$B45,TEXTJOIN(" ",TRUE,$C$45:$C45))))) | F45: ==E45/D45
...

Sheet DEEPSEEK
A1: Service Name | B1: service_id | C1: api_base | D1: docs_url | E1: best_probe_status | F1: best_probe_latency_ms | G1: best_probe_bytes | H1: rank | I1: relevance_pct | J1: sdas | K1: fca | L1: ifs | M1: ssi | N1: ORIGINAL_NAME
A2: Maps API | B2: google_maps__geocoding_forward | C2: https://maps.googleapis.com | D2: https://developers.google.com/maps/documentation/geocoding/overview | H2: 1 | I2: 99.5 | N2: Google Maps Geocoding API
A3: Api API | B3: mapbox__geocoding_forward | C3: https://api.mapbox.com | D3: https://docs.mapbox.com/api/search/geocoding/ | H3: 2 | I3: 97.8 | N3: Mapbox Geocoding API
A4: Geocode API | B4: here__geocoding_forward | C4: https://geocode.search.hereapi.com | D4: https://developer.here.com/documentation/geocoding-search-api/dev_guide/index.html | H4: 3 | I4: 95.2 | N4: HERE Geocoding and Search API
A5: Api API | B5: opencage__geocoding_forward | C5: https://api.opencagedata.com | D5: https://opencagedata.com/api | H5: 4 | I5: 92.7 | N5: OpenCage Geocoding API
A6: Us1 API | B6: locationiq__geocoding_forward | C6: https://us1.locationiq.com | D6: https://locationiq.com/docs | H6: 5 | I6: 89.3 | N6: LocationIQ Geocoding API
A7: Dev API | B7: bing_maps__locations_query | C7: https://dev.virtualearth.net | D7: https://docs.microsoft.com/en-us/bingmaps/rest-services/locations/ | H7: 6 | I7: 86.1 | N7: Bing Maps Locations API
A8: Api API | B8: tomtom__search_geocoding | C8: https://api.tomtom.com | D8: https://developer.tomtom.com/search-api/documentation/geocoding-service/geocode | E8: 403 | F8: 27 | G8: 94 | H8: 7 | I8: 82.8 | J8: 0.435 | K8: 0.8 | L8: 0.25 | M8: 0 | N8: TomTom Search API - Geocoding
A9: Mapquestapi API | B9: mapquest__geocoding_address | C9: https://www.mapquestapi.com | D9: https://developer.mapquest.com/documentation/geocoding-api/ | H9: 8 | I9: 79.4 | N9: MapQuest Geocoding API
A10: Api API | B10: geocodio__geocoding_forward | C10: https://api.geocod.io | D10: https://www.geocod.io/docs/ | H10: 9 | I10: 75.9 | N10: Geocodio Geocoding API
A11: Us-street API | B11: smartystreets__us-street-address | C11: https://us-street.api.smartystreets.com | D11: https://www.smarty.com/docs/cloud/us-street-api | H11: 10 | I11: 72.3 | N11: Smarty US Street Address API
A13: OVERLAP DEEPSEEK vs GPT
A14: Comparison | B14: A_Name | C14: B_Original | D14: k | E14: OverlapCount | F14: Overlap
B15: ==IFERROR(INDEX('CLEAN'!$E$2:$E$9999,1),"") | C15: ==IFERROR(INDEX('CLEAN'!$B$2:$B$9999,1),"") | D15: 1 | E15: =SUMPRODUCT(N(ISNUMBER(SEARCH($B$15:$B15,TEXTJOIN(" ",TRUE,$C$15:$C15))))) | F15: ==E15/D15
B16: ==IFERROR(INDEX('CLEAN'!$E$2:$E$9999,2),"") | C16: ==IFERROR(INDEX('CLEAN'!$B$2:$B$9999,2),"") | D16: 2 | E16: =SUMPRODUCT(N(ISNUMBER(SEARCH($B$15:$B16,TEXTJOIN(" ",TRUE,$C$15:$C16))))) | F16: ==E16/D16
B17: ==IFERROR(INDEX('CLEAN'!$E$2:$E$9999,3),"") | C17: ==IFERROR(INDEX('CLEAN'!$B$2:$B$9999,3),"") | D17: 3 | E17: =SUMPRODUCT(N(ISNUMBER(SEARCH($B$15:$B17,TEXTJOIN(" ",TRUE,$C$15:$C17))))) | F17: ==E17/D17
B18: ==IFERROR(INDEX('CLEAN'!$E$2:$E$9999,4),"") | C18: ==IFERROR(INDEX('CLEAN'!$B$2:$B$9999,4),"") | D18: 4 | E18: =SUMPRODUCT(N(ISNUMBER(SEARCH($B$15:$B18,TEXTJOIN(" ",TRUE,$C$15:$C18))))) | F18: ==E18/D18
B19: ==IFERROR(INDEX('CLEAN'!$E$2:$E$9999,5),"") | C19: ==IFERROR(INDEX('CLEAN'!$B$2:$B$9999,5),"") | D19: 5 | E19: =SUMPRODUCT(N(ISNUMBER(SEARCH($B$15:$B19,TEXTJOIN(" ",TRUE,$C$15:$C19))))) | F19: ==E19/D19
B20: ==IFERROR(INDEX('CLEAN'!$E$2:$E$9999,6),"") | C20: ==IFERROR(INDEX('CLEAN'!$B$2:$B$9999,6),"") | D20: 6 | E20: =SUMPRODUCT(N(ISNUMBER(SEARCH($B$15:$B20,TEXTJOIN(" ",TRUE,$C$15:$C20))))) | F20: ==E20/D20
B21: ==IFERROR(INDEX('CLEAN'!$E$2:$E$9999,7),"") | C21: ==IFERROR(INDEX('CLEAN'!$B$2:$B$9999,7),"") | D21: 7 | E21: =SUMPRODUCT(N(ISNUMBER(SEARCH($B$15:$B21,TEXTJOIN(" ",TRUE,$C$15:$C21))))) | F21: ==E21/D21
B22: ==IFERROR(INDEX('CLEAN'!$E$2:$E$9999,8),"") | C22: ==IFERROR(INDEX('CLEAN'!$B$2:$B$9999,8),"") | D22: 8 | E22: =SUMPRODUCT(N(ISNUMBER(SEARCH($B$15:$B22,TEXTJOIN(" ",TRUE,$C$15:$C22))))) | F22: ==E22/D22
B23: ==IFERROR(INDEX('CLEAN'!$E$2:$E$9999,9),"") | C23: ==IFERROR(INDEX('CLEAN'!$B$2:$B$9999,9),"") | D23: 9 | E23: =SUMPRODUCT(N(ISNUMBER(SEARCH($B$15:$B23,TEXTJOIN(" ",TRUE,$C$15:$C23))))) | F23: ==E23/D23
B24: ==IFERROR(INDEX('CLEAN'!$E$2:$E$9999,10),"") | C24: ==IFERROR(INDEX('CLEAN'!$B$2:$B$9999,10),"") | D24: 10 | E24: =SUMPRODUCT(N(ISNUMBER(SEARCH($B$15:$B24,TEXTJOIN(" ",TRUE,$C$15:$C24))))) | F24: ==E24/D24
D26: AO | F26: ==AVERAGE(F15:F24)
A28: OVERLAP DEEPSEEK vs CLAUDE
A29: Comparison | B29: A_Name | C29: B_Original | D29: k | E29: OverlapCount | F29: Overlap
B30: ==IFERROR(INDEX('CLEAN'!$E$2:$E$9999,1),"") | C30: ==IFERROR(INDEX('CLEAN'!$C$2:$C$9999,1),"") | D30: 1 | E30: =SUMPRODUCT(N(ISNUMBER(SEARCH($B$30:$B30,TEXTJOIN(" ",TRUE,$C$30:$C30))))) | F30: ==E30/D30
B31: ==IFERROR(INDEX('CLEAN'!$E$2:$E$9999,2),"") | C31: ==IFERROR(INDEX('CLEAN'!$C$2:$C$9999,2),"") | D31: 2 | E31: =SUMPRODUCT(N(ISNUMBER(SEARCH($B$30:$B31,TEXTJOIN(" ",TRUE,$C$30:$C31))))) | F31: ==E31/D31
B32: ==IFERROR(INDEX('CLEAN'!$E$2:$E$9999,3),"") | C32: ==IFERROR(INDEX('CLEAN'!$C$2:$C$9999,3),"") | D32: 3 | E32: =SUMPRODUCT(N(ISNUMBER(SEARCH($B$30:$B32,TEXTJOIN(" ",TRUE,$C$30:$C32))))) | F32: ==E32/D32
B33: ==IFERROR(INDEX('CLEAN'!$E$2:$E$9999,4),"") | C33: ==IFERROR(INDEX('CLEAN'!$C$2:$C$9999,4),"") | D33: 4 | E33: =SUMPRODUCT(N(ISNUMBER(SEARCH($B$30:$B33,TEXTJOIN(" ",TRUE,$C$30:$C33))))) | F33: ==E33/D33
B34: ==IFERROR(INDEX('CLEAN'!$E$2:$E$9999,5),"") | C34: ==IFERROR(INDEX('CLEAN'!$C$2:$C$9999,5),"") | D34: 5 | E34: =SUMPRODUCT(N(ISNUMBER(SEARCH($B$30:$B34,TEXTJOIN(" ",TRUE,$C$30:$C34))))) | F34: ==E34/D34
B35: ==IFERROR(INDEX('CLEAN'!$E$2:$E$9999,6),"") | C35: ==IFERROR(INDEX('CLEAN'!$C$2:$C$9999,6),"") | D35: 6 | E35: =SUMPRODUCT(N(ISNUMBER(SEARCH($B$30:$B35,TEXTJOIN(" ",TRUE,$C$30:$C35))))) | F35: ==E35/D35
B36: ==IFERROR(INDEX('CLEAN'!$E$2:$E$9999,7),"") | C36: ==IFERROR(INDEX('CLEAN'!$C$2:$C$9999,7),"") | D36: 7 | E36: =SUMPRODUCT(N(ISNUMBER(SEARCH($B$30:$B36,TEXTJOIN(" ",TRUE,$C$30:$C36))))) | F36: ==E36/D36
B37: ==IFERROR(INDEX('CLEAN'!$E$2:$E$9999,8),"") | C37: ==IFERROR(INDEX('CLEAN'!$C$2:$C$9999,8),"") | D37: 8 | E37: =SUMPRODUCT(N(ISNUMBER(SEARCH($B$30:$B37,TEXTJOIN(" ",TRUE,$C$30:$C37))))) | F37: ==E37/D37
B38: ==IFERROR(INDEX('CLEAN'!$E$2:$E$9999,9),"") | C38: ==IFERROR(INDEX('CLEAN'!$C$2:$C$9999,9),"") | D38: 9 | E38: =SUMPRODUCT(N(ISNUMBER(SEARCH($B$30:$B38,TEXTJOIN(" ",TRUE,$C$30:$C38))))) | F38: ==E38/D38
B39: ==IFERROR(INDEX('CLEAN'!$E$2:$E$9999,10),"") | C39: ==IFERROR(INDEX('CLEAN'!$C$2:$C$9999,10),"") | D39: 10 | E39: =SUMPRODUCT(N(ISNUMBER(SEARCH($B$30:$B39,TEXTJOIN(" ",TRUE,$C$30:$C39))))) | F39: ==E39/D39
D41: AO | F41: ==AVERAGE(F30:F39)
A43: OVERLAP DEEPSEEK vs GEMINI
A44: Comparison | B44: A_Name | C44: B_Original | D44: k | E44: OverlapCount | F44: Overlap
B45: ==IFERROR(INDEX('CLEAN'!$E$2:$E$9999,1),"") | C45: ==IFERROR(INDEX('CLEAN'!$D$2:$D$9999,1),"") | D45: 1 | E45: =SUMPRODUCT(N(ISNUMBER(SEARCH($B$45:$B45,TEXTJOIN(" ",TRUE,$C$45:$C45))))) | F45: ==E45/D45
...

Sheet MISTRAL
A1: Service Name | B1: service_id | C1: api_base | D1: docs_url | E1: best_probe_status | F1: best_probe_latency_ms | G1: best_probe_bytes | H1: rank | I1: relevance_pct | J1: sdas | K1: fca | L1: ifs | M1: ssi | N1: ORIGINAL_NAME
A2: Maps API | B2: google__geocoding_api | C2: https://maps.googleapis.com/maps/api/geocode | D2: https://developers.google.com/maps/documentation/geocoding/overview | E2: 400 | F2: 30 | G2: 166 | H2: 1 | I2: 100 | J2: 0.345 | K2: 0.6 | L2: 0.25 | M2: 0 | N2: Google Maps Geocoding API
A3: Api API | B3: opencage__geocoding_api | C3: https://api.opencagedata.com/geocode/v1 | D3: https://opencagedata.com/api | H3: 2 | I3: 99.5 | N3: OpenCage Geocoding API
A4: Api API | B4: mapbox__geocoding_api | C4: https://api.mapbox.com/geocoding/v5 | D4: https://docs.mapbox.com/api/search/geocoding/ | H4: 3 | I4: 99 | N4: Mapbox Geocoding API
A5: Us1 API | B5: locationiq__geocoding_api | C5: https://us1.locationiq.com/v1 | D5: https://docs.locationiq.com/docs/geocoding | H5: 4 | I5: 98.5 | N5: LocationIQ Geocoding API
A6: Api API | B6: geoapify__geocoding_api | C6: https://api.geoapify.com/v1/geocode | D6: https://www.geoapify.com/geocoding-api | H6: 5 | I6: 98 | N6: Geoapify Geocoding API
A7: Geocoder API | B7: here__geocoding_api | C7: https://geocoder.ls.hereapi.com/6.2 | D7: https://developer.here.com/products/geocoding | H7: 6 | I7: 97.5 | N7: HERE Geocoding API
A8: Api API | B8: tomtom__geocoding_api | C8: https://api.tomtom.com/search/2 | D8: https://developer.tomtom.com/search-api/search-api-documentation/geocode/geocode | H8: 7 | I8: 97 | N8: TomTom Geocoding API
A9: Mapquestapi API | B9: mapquest__geocoding_api | C9: http://www.mapquestapi.com/geocoding/v1 | D9: https://developer.mapquest.com/documentation/geocoding-api/ | H9: 8 | I9: 96.5 | N9: MapQuest Geocoding API
A10: Api API | B10: positionstack__geocoding_api | C10: http://api.positionstack.com/v1 | D10: https://positionstack.com/documentation | H10: 9 | I10: 96 | N10: PositionStack Geocoding API
A11: Geocode API | B11: geocode_maps__free_geocoding_api | C11: https://geocode.maps.co | D11: https://geocode.maps.co/ | H11: 10 | I11: 95.5 | N11: Geocode.maps.co Free Geocoding API
A13: OVERLAP MISTRAL vs GPT
A14: Comparison | B14: A_Name | C14: B_Original | D14: k | E14: OverlapCount | F14: Overlap
B15: ==IFERROR(INDEX('CLEAN'!$F$2:$F$9999,1),"") | C15: ==IFERROR(INDEX('CLEAN'!$B$2:$B$9999,1),"") | D15: 1 | E15: =SUMPRODUCT(N(ISNUMBER(SEARCH($B$15:$B15,TEXTJOIN(" ",TRUE,$C$15:$C15))))) | F15: ==E15/D15
B16: ==IFERROR(INDEX('CLEAN'!$F$2:$F$9999,2),"") | C16: ==IFERROR(INDEX('CLEAN'!$B$2:$B$9999,2),"") | D16: 2 | E16: =SUMPRODUCT(N(ISNUMBER(SEARCH($B$15:$B16,TEXTJOIN(" ",TRUE,$C$15:$C16))))) | F16: ==E16/D16
B17: ==IFERROR(INDEX('CLEAN'!$F$2:$F$9999,3),"") | C17: ==IFERROR(INDEX('CLEAN'!$B$2:$B$9999,3),"") | D17: 3 | E17: =SUMPRODUCT(N(ISNUMBER(SEARCH($B$15:$B17,TEXTJOIN(" ",TRUE,$C$15:$C17))))) | F17: ==E17/D17
B18: ==IFERROR(INDEX('CLEAN'!$F$2:$F$9999,4),"") | C18: ==IFERROR(INDEX('CLEAN'!$B$2:$B$9999,4),"") | D18: 4 | E18: =SUMPRODUCT(N(ISNUMBER(SEARCH($B$15:$B18,TEXTJOIN(" ",TRUE,$C$15:$C18))))) | F18: ==E18/D18
B19: ==IFERROR(INDEX('CLEAN'!$F$2:$F$9999,5),"") | C19: ==IFERROR(INDEX('CLEAN'!$B$2:$B$9999,5),"") | D19: 5 | E19: =SUMPRODUCT(N(ISNUMBER(SEARCH($B$15:$B19,TEXTJOIN(" ",TRUE,$C$15:$C19))))) | F19: ==E19/D19
B20: ==IFERROR(INDEX('CLEAN'!$F$2:$F$9999,6),"") | C20: ==IFERROR(INDEX('CLEAN'!$B$2:$B$9999,6),"") | D20: 6 | E20: =SUMPRODUCT(N(ISNUMBER(SEARCH($B$15:$B20,TEXTJOIN(" ",TRUE,$C$15:$C20))))) | F20: ==E20/D20
B21: ==IFERROR(INDEX('CLEAN'!$F$2:$F$9999,7),"") | C21: ==IFERROR(INDEX('CLEAN'!$B$2:$B$9999,7),"") | D21: 7 | E21: =SUMPRODUCT(N(ISNUMBER(SEARCH($B$15:$B21,TEXTJOIN(" ",TRUE,$C$15:$C21))))) | F21: ==E21/D21
B22: ==IFERROR(INDEX('CLEAN'!$F$2:$F$9999,8),"") | C22: ==IFERROR(INDEX('CLEAN'!$B$2:$B$9999,8),"") | D22: 8 | E22: =SUMPRODUCT(N(ISNUMBER(SEARCH($B$15:$B22,TEXTJOIN(" ",TRUE,$C$15:$C22))))) | F22: ==E22/D22
B23: ==IFERROR(INDEX('CLEAN'!$F$2:$F$9999,9),"") | C23: ==IFERROR(INDEX('CLEAN'!$B$2:$B$9999,9),"") | D23: 9 | E23: =SUMPRODUCT(N(ISNUMBER(SEARCH($B$15:$B23,TEXTJOIN(" ",TRUE,$C$15:$C23))))) | F23: ==E23/D23
B24: ==IFERROR(INDEX('CLEAN'!$F$2:$F$9999,10),"") | C24: ==IFERROR(INDEX('CLEAN'!$B$2:$B$9999,10),"") | D24: 10 | E24: =SUMPRODUCT(N(ISNUMBER(SEARCH($B$15:$B24,TEXTJOIN(" ",TRUE,$C$15:$C24))))) | F24: ==E24/D24
D26: AO | F26: ==AVERAGE(F15:F24)
A28: OVERLAP MISTRAL vs CLAUDE
A29: Comparison | B29: A_Name | C29: B_Original | D29: k | E29: OverlapCount | F29: Overlap
B30: ==IFERROR(INDEX('CLEAN'!$F$2:$F$9999,1),"") | C30: ==IFERROR(INDEX('CLEAN'!$C$2:$C$9999,1),"") | D30: 1 | E30: =SUMPRODUCT(N(ISNUMBER(SEARCH($B$30:$B30,TEXTJOIN(" ",TRUE,$C$30:$C30))))) | F30: ==E30/D30
B31: ==IFERROR(INDEX('CLEAN'!$F$2:$F$9999,2),"") | C31: ==IFERROR(INDEX('CLEAN'!$C$2:$C$9999,2),"") | D31: 2 | E31: =SUMPRODUCT(N(ISNUMBER(SEARCH($B$30:$B31,TEXTJOIN(" ",TRUE,$C$30:$C31))))) | F31: ==E31/D31
B32: ==IFERROR(INDEX('CLEAN'!$F$2:$F$9999,3),"") | C32: ==IFERROR(INDEX('CLEAN'!$C$2:$C$9999,3),"") | D32: 3 | E32: =SUMPRODUCT(N(ISNUMBER(SEARCH($B$30:$B32,TEXTJOIN(" ",TRUE,$C$30:$C32))))) | F32: ==E32/D32
B33: ==IFERROR(INDEX('CLEAN'!$F$2:$F$9999,4),"") | C33: ==IFERROR(INDEX('CLEAN'!$C$2:$C$9999,4),"") | D33: 4 | E33: =SUMPRODUCT(N(ISNUMBER(SEARCH($B$30:$B33,TEXTJOIN(" ",TRUE,$C$30:$C33))))) | F33: ==E33/D33
B34: ==IFERROR(INDEX('CLEAN'!$F$2:$F$9999,5),"") | C34: ==IFERROR(INDEX('CLEAN'!$C$2:$C$9999,5),"") | D34: 5 | E34: =SUMPRODUCT(N(ISNUMBER(SEARCH($B$30:$B34,TEXTJOIN(" ",TRUE,$C$30:$C34))))) | F34: ==E34/D34
B35: ==IFERROR(INDEX('CLEAN'!$F$2:$F$9999,6),"") | C35: ==IFERROR(INDEX('CLEAN'!$C$2:$C$9999,6),"") | D35: 6 | E35: =SUMPRODUCT(N(ISNUMBER(SEARCH($B$30:$B35,TEXTJOIN(" ",TRUE,$C$30:$C35))))) | F35: ==E35/D35
B36: ==IFERROR(INDEX('CLEAN'!$F$2:$F$9999,7),"") | C36: ==IFERROR(INDEX('CLEAN'!$C$2:$C$9999,7),"") | D36: 7 | E36: =SUMPRODUCT(N(ISNUMBER(SEARCH($B$30:$B36,TEXTJOIN(" ",TRUE,$C$30:$C36))))) | F36: ==E36/D36
B37: ==IFERROR(INDEX('CLEAN'!$F$2:$F$9999,8),"") | C37: ==IFERROR(INDEX('CLEAN'!$C$2:$C$9999,8),"") | D37: 8 | E37: =SUMPRODUCT(N(ISNUMBER(SEARCH($B$30:$B37,TEXTJOIN(" ",TRUE,$C$30:$C37))))) | F37: ==E37/D37
B38: ==IFERROR(INDEX('CLEAN'!$F$2:$F$9999,9),"") | C38: ==IFERROR(INDEX('CLEAN'!$C$2:$C$9999,9),"") | D38: 9 | E38: =SUMPRODUCT(N(ISNUMBER(SEARCH($B$30:$B38,TEXTJOIN(" ",TRUE,$C$30:$C38))))) | F38: ==E38/D38
B39: ==IFERROR(INDEX('CLEAN'!$F$2:$F$9999,10),"") | C39: ==IFERROR(INDEX('CLEAN'!$C$2:$C$9999,10),"") | D39: 10 | E39: =SUMPRODUCT(N(ISNUMBER(SEARCH($B$30:$B39,TEXTJOIN(" ",TRUE,$C$30:$C39))))) | F39: ==E39/D39
D41: AO | F41: ==AVERAGE(F30:F39)
A43: OVERLAP MISTRAL vs GEMINI
A44: Comparison | B44: A_Name | C44: B_Original | D44: k | E44: OverlapCount | F44: Overlap
B45: ==IFERROR(INDEX('CLEAN'!$F$2:$F$9999,1),"") | C45: ==IFERROR(INDEX('CLEAN'!$D$2:$D$9999,1),"") | D45: 1 | E45: =SUMPRODUCT(N(ISNUMBER(SEARCH($B$45:$B45,TEXTJOIN(" ",TRUE,$C$45:$C45))))) | F45: ==E45/D45
...
